Workbook
Name \0: #N/A
Name \a: #N/A
Name \b: #N/A
Name \c: #N/A
Name \d: #N/A
Name \e: #N/A
Name \f: #N/A
Name \g: #N/A
Name \h: #N/A
Name \i: #N/A
Name \j: #N/A
Name \k: #N/A
Name \KWS123: #N/A
Name \l: '[1]合成単価作成表-BLDG'!#REF!
Name \m: #N/A
Name \n: #N/A
Name \p: #N/A
Name \q: #N/A
Name \r: #REF!
Name \s: #N/A
Name \t: #N/A
Name \z: #N/A
Name _______________________wer12: #N/A
Name ______________________wer12: #N/A
Name _____________________wer12: #N/A
Name ____________________wer12: #N/A
Name ___________________wer12: #N/A
Name __________________wer12: #N/A
Name _________________wer12: #N/A
Name ________________Esc1: #REF!
Name ________________pay5: #REF!
Name ________________PCF1: #REF!
Name ________________SVF1: #REF!
Name ________________wer12: #N/A
Name _______________Esc1: #REF!
Name _______________pay5: #REF!
Name _______________PCF1: #REF!
Name _______________SVF1: #REF!
Name _______________wer12: #N/A
Name ______________AOC2: #REF!
Name ______________DDD2: #N/A
Name ______________DDD3: #N/A
Name ______________DDD4: #N/A
Name ______________DDD5: #N/A
Name ______________DEL1: '[3]공정율 기초 Data'!$B$97
Name ______________DEL2: '[3]공정율 기초 Data'!$B$98
Name ______________ELL45: #REF!
Name ______________ELL90: #REF!
Name ______________Esc1: #REF!
Name ______________ins1: '[4]가격분석@1100(990104)'!$AC$10
Name ______________MPR1: #N/A
Name ______________MPR2: #N/A
Name ______________MPR3: #N/A
Name ______________ofc1: #REF!
Name ______________pay5: #REF!
Name ______________PCF1: #REF!
Name ______________RE100: #REF!
Name ______________RE104: #REF!
Name ______________RE112: #REF!
Name ______________RE26: #REF!

Sheet S(Week)
A1: Progress
A2: ='L3'!A1 -> DD : 01-Apr-2026 (159th Weeks)
N3: 46113
A4: S/N | B4: Phase | D4: Budget | E4: Weight Factor | F4: Up to Last Week (~03/25) | I4: This Week (~03/26~04/01) | L4: Accumulate (~04/01)
F5: Plan | G5: Act | H5: Gap | I5: Plan | J5: Act | K5: Gap | L5: Plan | M5: Act | N5: Gap
A6: 1 | B6: Construction | D6: =Sheet2!F2 -> 50102810 | E6: 0.5 | F6: 0.99495044 | G6: 0.34883743 | H6: -0.64611302 | I6: =L6-F6 -> 6.6782681e-05 | J6: =M6-G6 -> 0.0041356911 | K6: =J6-I6 -> 0.0040689084 | L6: ='L3'!I1 -> 0.99501723 | M6: ='L3'!N1 -> 0.35297312 | N6: =M6-L6 -> -0.64204411

Sheet L3
A1: DD : 01-Apr-2026 (159th Weeks) | D1: =D4 -> 50102810 | E1: =SUMIFS($E$10:$E$2459,$A$10:$A$2459,"9") -> 49853159 | F1: =IFERROR(SUMIFS($F$10:$F$2459,$A$10:$A$2459,"9"),0) -> 17684945 | H1: Total Plan | I1: =E1/D1 -> 0.99501723 | L1: Total Actual | N1: =F1/D1 -> 0.35297312 | T1: Gap | U1: =N1-I1 -> -0.64204411
A2: WBS Level | B2: Activity ID | C2: Activity Name | D2: Budgeted Units | E2: Plan Units | F2: Actual Units | H2: Start | I2: Finish | J2: Duration | L2: Actual Start | N2: Actual Finish | P2: Quantities | U2: GAP | V2: Activity Status | W2: Weekly Progress | AC2: Dep | AD2: Local Staff | AE2: Korean Staff | AK2: 45109 | AL2: 45116 | AM2: 45123 | AN2: 45130 | AO2: 45137 | AP2: 45144 | AQ2: 45151 | AR2: 45158 | AS2: 45165 | AT2: 45172 | AU2: 45179 | AV2: 45186 | AW2: 45193 | AX2: 45200 | AY2: 45207 | AZ2: 45214 | BA2: 45221 | BB2: 45228 | BC2: 45235 | BD2: 45242 | BE2: 45249 | BF2: 45256 | BG2: 45263 | BH2: 45270 | BI2: 45277 | BJ2: 45284 | BK2: 45291 | BL2: 45298 | BM2: 45305 | BN2: 45312 | BO2: 45319 | BP2: 45326 | BQ2: 45333 | BR2: 45340 | BS2: 45347 | BT2: 45354 | BU2: 45361 | BV2: 45368 | BW2: 45375 | BX2: 45382 | BY2: 45389 | BZ2: 45396 | CA2: 45403 | CB2: 45410 | CC2: 45417 | CD2: 45424 | CE2: 45431 | CF2: 45438 | CG2: 45445 | CH2: 45452 | CI2: 45459 | CJ2: 45466 | CK2: 45473 | CL2: 45480 | CM2: 45487 | CN2: 45494 | CO2: 45501 | CP2: 45508 | CQ2: 45515 | CR2: 45522 | CS2: 45529 | CT2: 45536 | CU2: 45543 | CV2: 45550 | CW2: 45557 | CX2: 45564 | CY2: 45571 | CZ2: 45578 | DA2: 45585 | DB2: 45592 | DC2: 45599 | DD2: 45606 | DE2: 45613 | DF2: 45620 | DG2: 45627 | DH2: 45634 | DI2: 45641 | DJ2: 45648 | DK2: 45655 | DL2: 45662 | DM2: 45669 | DN2: 45676 | DO2: 45683 | DP2: 45690 | DQ2: 45697 | DR2: 45704 | DS2: 45711 | DT2: 45718 | DU2: 45725 | DV2: 45732 | DW2: 45739 | DX2: 45746 | DY2: 45753 | DZ2: 45760 | EA2: 45767 | EB2: 45774 | EC2: 45781 | ED2: 45788 | EE2: 45795 | EF2: 45802 | EG2: 45809 | EH2: 45816 | EI2: 45823 | EJ2: 45830 | EK2: 45837 | EL2: 45844 | EM2: 45851 | EN2: 45858 | EO2: 45865 | EP2: 45872 | EQ2: 45879 | ER2: 45886 | ES2: 45893 | ET2: 45900 | EU2: 45907 | EV2: 45914 | EW2: 45921 | EX2: 45928 | EY2: 45935 | EZ2: 45942 | FA2: 45949 | FB2: 45956 | FC2: 45963 | FD2: 45970 | FE2: 45977 | FF2: 45984 | FG2: 45991 | FH2: 45998 | FI2: 46005 | FJ2: 46012 | FK2: 46019 | FL2: 46026 | FM2: 46033 | FN2: 46040 | FO2: 46047 | FP2: 46054 | FQ2: 46061 | FR2: 46068 | FS2: 46075 | FT2: 46082 | FU2: 46089 | FV2: 46096 | FW2: 46103 | FX2: 46110 | FY2: 46117 | FZ2: 46124 | GA2: 46131 | GB2: 46138 | GC2: 46145 | GD2: 46152 | GE2: 46159 | GF2: 46166 | GG2: 46173 | GH2: 46180
G3: %(A) | P3: Actual Quantities | R3: Design Quantities | T3: %(B) | U3: (B-A) | W3: Previous week Total | X3: unit | Y3: This Week | Z3: unit | AA3: Actual Total | AB3: unit
A4: 0 | B4: Construction of a 1000MW CCGT Power Plant in the Turkistan Region, Main Site_New Site | D4: 50102810 | H4: 45089 | I4: 46181 | J4: 937 | AP4: 467 | AQ4: 467 | AR4: 467 | AS4: 467 | AT4: 467 | AU4: 11898 | AV4: 34759 | AW4: 29273 | AX4: 13406 | AY4: 7629 | AZ4: 9226 | BA4: 13606 | BB4: 13606 | BC4: 13541 | BD4: 13139 | BE4: 12099 | BF4: 6570 | BG4: 2728 | BM4: 1104 | BN4: 1073 | BO4: 817 | BP4: 543 | BQ4: 266 | BR4: 42 | CC4: 70 | CD4: 551 | CE4: 3058 | CF4: 17583 | CG4: 82476 | CH4: 88153 | CI4: 96368 | CJ4: 153489 | CK4: 235381 | CL4: 294696 | CM4: 434172 | CN4: 472392 | CO4: 378701 | CP4: 286904 | CQ4: 263291 | CR4: 208839 | CS4: 219254 | CT4: 239920 | CU4: 309852 | CV4: 298282 | CW4: 359332 | CX4: 615241 | CY4: 764704 | CZ4: 795831 | DA4: 766045 | DB4: 742097 | DC4: 847236 | DD4: 1030887 | DE4: 875032 | DF4: 743328 | DG4: 780703 | DH4: 790027 | DI4: 544088 | DJ4: 403905 | DK4: 452610 | DL4: 669855 | DM4: 945990 | DN4: 1034870 | DO4: 867829 | DP4: 812973 | DQ4: 861984 | DR4: 804109 | DS4: 547989 | DT4: 609346 | DU4: 505644 | DV4: 454729 | DW4: 565519 | DX4: 426537 | DY4: 332504 | DZ4: 411789 | EA4: 433324 | EB4: 826816 | EC4: 1071411 | ED4: 814336 | EE4: 721060 | EF4: 578530 | EG4: 606317 | EH4: 515061 | EI4: 513031 | EJ4: 608194 | EK4: 981210 | EL4: 1016836 | EM4: 988354 | EN4: 1083102 | EO4: 925063 | EP4: 929038 | EQ4: 1009933 | ER4: 791577 | ES4: 711563 | ET4: 632454 | EU4: 593631 | EV4: 597826 | EW4: 763890 | EX4: 771921 | EY4: 782271 | EZ4: 676671 | FA4: 930283 | FB4: 673632 | FC4: 785599 | FD4: 384719 | FE4: 417420 | FF4: 349677 | FG4: 277631 | FH4: 191653 | FI4: 192659 | FJ4: 163731 | FK4: 187392 | FL4: 177892 | FM4: 86261 | FN4: 72886 | FO4: 62614 | FP4: 52069 | FQ4: 29886 | FR4: 90549 | FS4: 81632 | FT4: 52387 | FU4: 97548 | FV4: 46710 | FW4: 10720 | FX4: 3346 | FY4: 298 | FZ4: 2808 | GA4: 8671 | GB4: 6672 | GC4: 10849 | GD4: 34581 | GE4: 12095 | GF4: 14258 | GG4: 14258 | GH4: 2163
A5: 1 | B5: Plant General | D5: 177344 | H5: 45089 | I5: 45266 | J5: 152 | AU5: 11431 | AV5: 34292 | AW5: 28806 | AX5: 12940 | AY5: 7162 | AZ5: 8760 | BA5: 13139 | BB5: 13139 | BC5: 13139 | BD5: 13139 | BE5: 12099 | BF5: 6570 | BG5: 2728
A6: 2 | B6: General Civil Works | D6: 177344 | H6: 45089 | I6: 45266 | J6: 152 | AU6: 11431 | AV6: 34292 | AW6: 28806 | AX6: 12940 | AY6: 7162 | AZ6: 8760 | BA6: 13139 | BB6: 13139 | BC6: 13139 | BD6: 13139 | BE6: 12099 | BF6: 6570 | BG6: 2728
A7: 3 | B7: Site Preparation | D7: 177344 | H7: 45184 | I7: 45266 | J7: 70 | AU7: 11431 | AV7: 34292 | AW7: 28806 | AX7: 12940 | AY7: 7162 | AZ7: 8760 | BA7: 13139 | BB7: 13139 | BC7: 13139 | BD7: 13139 | BE7: 12099 | BF7: 6570 | BG7: 2728
A8: 4 | B8: Construction Management | D8: 88672 | H8: 45184 | I8: 45266 | J8: 70 | AU8: 7117 | AV8: 21352 | AW8: 15866 | AZ8: 2190 | BA8: 6570 | BB8: 6570 | BC8: 6570 | BD8: 6570 | BE8: 6570 | BF8: 6570 | BG8: 2728
A9: 5 | B9: Civil & Architecture Team | D9: 88672 | H9: 45184 | I9: 45266 | J9: 70 | Y9: =IFERROR(IF(P9-W9=0, "", P9-W9), "") | AU9: 7117 | AV9: 21352 | AW9: 15866 | AZ9: 2190 | BA9: 6570 | BB9: 6570 | BC9: 6570 | BD9: 6570 | BE9: 6570 | BF9: 6570 | BG9: 2728
A10: 9 | B10: 0CF6010W10A7 | C10: Construction Permit & Mobilization | D10: 44336 | E10: {=SUMPRODUCT(($AK$2:$GH$2<='S(Week)'!$N$3)*(AK10:GH10)*1)} -> 44335 | F10: =IFERROR(E10*T10,0) -> 44335 | G10: =F10/E10 -> 1 | H10: 45184 | I10: 45198 | J10: 12 | M10: A | O10: A | P10: 100 | Q10: % | R10: 100 | S10: % | T10: =IFERROR($P10/$R10,0) -> 1 | U10: =T10-G10 -> 0 | V10: =IF(($M10="A")*($O10="A")>0,"Completed",IF($M10="A","In Progress","Not started")) -> Completed | W10: 100 | X10: % | Y10: =IFERROR(IF(P10-W10=0, "", P10-W10), "") | Z10: % | AA10: =IFERROR(W10+Y10,"") | AB10: % | AU10: 7117 | AV10: 21352 | AW10: 15866
A11: 9 | B11: 0CF6010W10A13 | C11: Temp. Facilities(Office & Camp, Fence Concrete Batch Plant & Others) | D11: 44336 | E11: {=SUMPRODUCT(($AK$2:$GH$2<='S(Week)'!$N$3)*(AK11:GH11)*1)} -> 44338 | F11: =IFERROR(E11*T11,0) -> 0 | H11: 45219 | I11: 45266 | J11: 40 | M11: A | O11: A | Q11: % | R11: 100 | S11: % | T11: =IFERROR($P11/$R11,0) -> 0 | U11: =T11-G11 -> 0 | V11: =IF(($M11="A")*($O11="A")>0,"Completed",IF($M11="A","In Progress","Not started")) -> Completed | X11: % | Y11: =IFERROR(IF(P11-W11=0, "", P11-W11), "") | Z11: % | AA11: =IFERROR(W11+Y11,"") | AB11: % | AZ11: 2190 | BA11: 6570 | BB11: 6570 | BC11: 6570 | BD11: 6570 | BE11: 6570 | BF11: 6570 | BG11: 2728
A12: 4 | B12: Survey & Soil Investigation | D12: 44336 | H12: 45184 | I12: 45208 | J12: 21 | Y12: =IFERROR(IF(P12-W12=0, "", P12-W12), "") | AA12: =IFERROR(W12+Y12,"") | AU12: 4313 | AV12: 12940 | AW12: 12940 | AX12: 12940 | AY12: 1204
A13: 5 | B13: Construction Management | D13: 44336 | H13: 45184 | I13: 45208 | J13: 21 | Y13: =IFERROR(IF(P13-W13=0, "", P13-W13), "") | AA13: =IFERROR(W13+Y13,"") | AU13: 4313 | AV13: 12940 | AW13: 12940 | AX13: 12940 | AY13: 1204
A14: 6 | B14: Civil & Architecture Team | D14: 44336 | H14: 45184 | I14: 45208 | J14: 21 | Y14: =IFERROR(IF(P14-W14=0, "", P14-W14), "") | AA14: =IFERROR(W14+Y14,"") | AU14: 4313 | AV14: 12940 | AW14: 12940 | AX14: 12940 | AY14: 1204
A15: 9 | B15: 0CF6010W10A8 | C15: Soil investigation | D15: 44336 | E15: {=SUMPRODUCT(($AK$2:$GH$2<='S(Week)'!$N$3)*(AK15:GH15)*1)} -> 44337 | F15: =IFERROR(E15*T15,0) -> 44337 | H15: 45184 | I15: 45208 | J15: 21 | M15: A | O15: A | P15: 100 | Q15: % | R15: 100 | S15: % | T15: =IFERROR($P15/$R15,0) -> 1 | V15: =IF(($M15="A")*($O15="A")>0,"Completed",IF($M15="A","In Progress","Not started")) -> Completed | W15: 100 | X15: % | Y15: =IFERROR(IF(P15-W15=0, "", P15-W15), "") | Z15: % | AA15: =IFERROR(W15+Y15,"") | AB15: % | AU15: 4313 | AV15: 12940 | AW15: 12940 | AX15: 12940 | AY15: 1204
A16: 4 | B16: Soil Improvement | D16: 44336 | H16: 45208 | I16: 45255 | J16: 40 | Y16: =IFERROR(IF(P16-W16=0, "", P16-W16), "") | AA16: =IFERROR(W16+Y16,"") | AY16: 5958 | AZ16: 6570 | BA16: 6570 | BB16: 6570 | BC16: 6570 | BD16: 6570 | BE16: 5529
A17: 5 | B17: Construction Management | D17: 44336 | H17: 45208 | I17: 45255 | J17: 40 | Y17: =IFERROR(IF(P17-W17=0, "", P17-W17), "") | AA17: =IFERROR(W17+Y17,"") | AY17: 5958 | AZ17: 6570 | BA17: 6570 | BB17: 6570 | BC17: 6570 | BD17: 6570 | BE17: 5529
A18: 6 | B18: Civil & Architecture Team | D18: 44336 | H18: 45208 | I18: 45255 | J18: 40 | Y18: =IFERROR(IF(P18-W18=0, "", P18-W18), "") | AA18: =IFERROR(W18+Y18,"") | AY18: 5958 | AZ18: 6570 | BA18: 6570 | BB18: 6570 | BC18: 6570 | BD18: 6570 | BE18: 5529
A19: 9 | B19: 0CF6010W10A18 | C19: Soil Improvement | D19: 44336 | E19: {=SUMPRODUCT(($AK$2:$GH$2<='S(Week)'!$N$3)*(AK19:GH19)*1)} -> 44337 | F19: =IFERROR(E19*T19,0) -> 44337 | H19: 45208 | I19: 45255 | J19: 40 | M19: A | O19: A | P19: 100 | Q19: % | R19: 100 | S19: % | T19: =IFERROR($P19/$R19,0) -> 1 | V19: =IF(($M19="A")*($O19="A")>0,"Completed",IF($M19="A","In Progress","Not started")) -> Completed | W19: 100 | X19: % | Y19: =IFERROR(IF(P19-W19=0, "", P19-W19), "") | Z19: % | AA19: =IFERROR(W19+Y19,"") | AB19: % | AY19: 5958 | AZ19: 6570 | BA19: 6570 | BB19: 6570 | BC19: 6570 | BD19: 6570 | BE19: 5529
A20: 3 | B20: Owner Scope | D20: 0 | H20: 45089 | I20: 45164 | J20: 66 | Y20: =IFERROR(IF(P20-W20=0, "", P20-W20), "") | AA20: =IFERROR(W20+Y20,"")
A21: 4 | B21: Construction Management | D21: 0 | H21: 45089 | I21: 45164 | J21: 66 | Y21: =IFERROR(IF(P21-W21=0, "", P21-W21), "") | AA21: =IFERROR(W21+Y21,"")
A22: 5 | B22: Civil & Architecture Team | D22: 0 | H22: 45089 | I22: 45164 | J22: 66 | Y22: =IFERROR(IF(P22-W22=0, "", P22-W22), "") | AA22: =IFERROR(W22+Y22,"")
A23: 9 | B23: 0CF6010W10A14 | C23: Site Access Road & Stie Leveling (By Owner) | D23: 0 | E23: {=SUMPRODUCT(($AK$2:$GH$2<='S(Week)'!$N$3)*(AK23:GH23)*1)} -> 0 | F23: =IFERROR(E23*T23,0) -> 0 | H23: 45089 | I23: 45164 | J23: 66 | T23: =IFERROR($P23/$R23,0) -> 0 | V23: =IF(($M23="A")*($O23="A")>0,"Completed",IF($M23="A","In Progress","Not started")) -> Not started | Y23: =IFERROR(IF(P23-W23=0, "", P23-W23), "") | AA23: =IFERROR(W23+Y23,"")
A24: 9 | B24: 0CF6010W10A15 | C24: Construction Power & Water (By Owner) | D24: 0 | E24: {=SUMPRODUCT(($AK$2:$GH$2<='S(Week)'!$N$3)*(AK24:GH24)*1)} -> 0 | F24: =IFERROR(E24*T24,0) -> 0 | H24: 45089 | I24: 45164 | J24: 66 | T24: =IFERROR($P24/$R24,0) -> 0 | V24: =IF(($M24="A")*($O24="A")>0,"Completed",IF($M24="A","In Progress","Not started")) -> Not started | Y24: =IFERROR(IF(P24-W24=0, "", P24-W24), "") | AA24: =IFERROR(W24+Y24,"")
A25: 9 | B25: 0CF6010W10A16 | C25: Telecom/communication line (By Owner) | D25: 0 | E25: {=SUMPRODUCT(($AK$2:$GH$2<='S(Week)'!$N$3)*(AK25:GH25)*1)} -> 0 | F25: =IFERROR(E25*T25,0) -> 0 | H25: 45089 | I25: 45164 | J25: 66 | T25: =IFERROR($P25/$R25,0) -> 0 | V25: =IF(($M25="A")*($O25="A")>0,"Completed",IF($M25="A","In Progress","Not started")) -> Not started | Y25: =IFERROR(IF(P25-W25=0, "", P25-W25), "") | AA25: =IFERROR(W25+Y25,"")
A26: 1 | B26: Power Plant Block #1 | D26: 21662709 | H26: 45400 | I26: 46100 | J26: 601 | Y26: =IFERROR(IF(P26-W26=0, "", P26-W26), "") | AA26: =IFERROR(W26+Y26,"") | CF26: 5794 | CG26: 58230 | CH26: 71936 | CI26: 87339 | CJ26: 133917 | CK26: 174978 | CL26: 221648 | CM26: 284944 | CN26: 285336 | CO26: 262295 | CP26: 209827 | CQ26: 157651 | CR26: 115700 | CS26: 101065 | CT26: 94822 | CU26: 103605 | CV26: 155632 | CW26: 206172 | CX26: 300265 | CY26: 390965 | CZ26: 437752 | DA26: 392954 | DB26: 355962 | DC26: 335742 | DD26: 276068 | DE26: 191723 | DF26: 151390 | DG26: 109927 | DH26: 157884 | DI26: 125771 | DJ26: 87249 | DK26: 85283 | DL26: 93075 | DM26: 78260 | DN26: 84588 | DO26: 92458 | DP26: 133199 | DQ26: 244761 | DR26: 352707 | DS26: 230794 | DT26: 333606 | DU26: 301749 | DV26: 231017 | DW26: 252945 | DX26: 184614 | DY26: 224397 | DZ26: 259238 | EA26: 259022 | EB26: 576177 | EC26: 920792 | ED26: 580260 | EE26: 429804 | EF26: 393367 | EG26: 468550 | EH26: 397101 | EI26: 398144 | EJ26: 377142 | EK26: 529188 | EL26: 697174 | EM26: 721492 | EN26: 739642 | EO26: 555997 | EP26: 561291 | EQ26: 636557 | ER26: 388290 | ES26: 293631 | ET26: 281546 | EU26: 208739 | EV26: 148429 | EW26: 263908 | EX26: 217003 | EY26: 186453 | EZ26: 179552 | FA26: 200195 | FB26: 175068 | FC26: 141881 | FD26: 113429 | FE26: 109761 | FF26: 38933 | FG26: 32345 | FH26: 11966 | FI26: 12416 | FJ26: 8977 | FK26: 9358 | FL26: 16317 | FM26: 13376 | FN26: 7420 | FO26: 4623 | FP26: 1726 | FQ26: 106 | FR26: 64195 | FS26: 30955 | FT26: 12832 | FU26: 12832 | FV26: 7508
A27: 2 | B27: Power Block #1 | D27: 17435761 | H27: 45444 | I27: 46100 | J27: 563 | Y27: =IFERROR(IF(P27-W27=0, "", P27-W27), "") | AA27: =IFERROR(W27+Y27,"") | CF27: 5794 | CG27: 58230 | CH27: 71627 | CI27: 85514 | CJ27: 132299 | CK27: 173593 | CL27: 220453 | CM27: 283984 | CN27: 284622 | CO27: 261754 | CP27: 209557 | CQ27: 157552 | CR27: 115700 | CS27: 101065 | CT27: 94822 | CU27: 102379 | CV27: 148994 | CW27: 187919 | CX27: 264405 | CY27: 343441 | CZ27: 392131 | DA27: 342666 | DB27: 291566 | DC27: 261842 | DD27: 212257 | DE27: 151516 | DF27: 127618 | DG27: 92688 | DH27: 140602 | DI27: 113185 | DJ27: 79968 | DK27: 71851 | DL27: 68545 | DM27: 54475 | DN27: 47354 | DO27: 45645 | DP27: 62809 | DQ27: 174644 | DR27: 298553 | DS27: 189217 | DT27: 264374 | DU27: 200308 | DV27: 186109 | DW27: 219172 | DX27: 159753 | DY27: 186577 | DZ27: 196911 | EA27: 179488 | EB27: 436677 | EC27: 759942 | ED27: 467124 | EE27: 327081 | EF27: 312006 | EG27: 398758 | EH27: 359188 | EI27: 366171 | EJ27: 319610 | EK27: 390612 | EL27: 564964 | EM27: 537044 | EN27: 646063 | EO27: 470354 | EP27: 474527 | EQ27: 532931 | ER27: 330851 | ES27: 236423 | ET27: 213683 | EU27: 78863 | EV27: 118377 | EW27: 197792 | EX27: 138927 | EY27: 130611 | EZ27: 113065 | FA27: 122377 | FB27: 99687 | FC27: 81378 | FD27: 43194 | FE27: 6726 | FF27: 2198 | FG27: 252 | FS27: 9602 | FT27: 12832 | FU27: 12832 | FV27: 7508
A28: 3 | B28: Main BLDG Complex (1.1) | D28: 3289373 | H28: 45444 | I28: 45820 | J28: 323 | Y28: =IFERROR(IF(P28-W28=0, "", P28-W28), "") | AA28: =IFERROR(W28+Y28,"") | CF28: 3986 | CG28: 47379 | CH28: 47379 | CI28: 47379 | CJ28: 47379 | CK28: 47379 | CL28: 47379 | CM28: 47379 | CN28: 35068 | CO28: 23914 | CP28: 23914 | CQ28: 23914 | CR28: 23914 | CS28: 23914 | CT28: 23914 | CU28: 23914 | CV28: 23914 | CW28: 1960 | DC28: 14096 | DD28: 21144 | DE28: 21144 | DF28: 21144 | DG28: 21144 | DH28: 68044 | DI28: 68120 | DJ28: 60766 | DK28: 57814 | DL28: 52618 | DM28: 47421 | DN28: 42948 | DO28: 38654 | DP28: 32802 | DQ28: 113516 | DR28: 166395 | DS28: 54028 | DT28: 84605 | DU28: 82760 | DV28: 80173 | DW28: 75219 | DX28: 73327 | DY28: 71387 | DZ28: 68179 | EA28: 64301 | EB28: 311896 | EC28: 486575 | ED28: 237189 | EE28: 118002 | EF28: 40820 | EG28: 26241 | EH28: 2923
A29: 4 | B29: Construction Management | D29: 3289373 | H29: 45444 | I29: 45820 | J29: 323 | Y29: =IFERROR(IF(P29-W29=0, "", P29-W29), "") | AA29: =IFERROR(W29+Y29,"") | CF29: 3986 | CG29: 47379 | CH29: 47379 | CI29: 47379 | CJ29: 47379 | CK29: 47379 | CL29: 47379 | CM29: 47379 | CN29: 35068 | CO29: 23914 | CP29: 23914 | CQ29: 23914 | CR29: 23914 | CS29: 23914 | CT29: 23914 | CU29: 23914 | CV29: 23914 | CW29: 1960 | DC29: 14096 | DD29: 21144 | DE29: 21144 | DF29: 21144 | DG29: 21144 | DH29: 68044 | DI29: 68120 | DJ29: 60766 | DK29: 57814 | DL29: 52618 | DM29: 47421 | DN29: 42948 | DO29: 38654 | DP29: 32802 | DQ29: 113516 | DR29: 166395 | DS29: 54028 | DT29: 84605 | DU29: 82760 | DV29: 80173 | DW29: 75219 | DX29: 73327 | DY29: 71387 | DZ29: 68179 | EA29: 64301 | EB29: 311896 | EC29: 486575 | ED29: 237189 | EE29: 118002 | EF29: 40820 | EG29: 26241 | EH29: 2923
A30: 5 | B30: Civil & Architecture Team | D30: 2099996 | H30: 45444 | I30: 45820 | J30: 323 | Y30: =IFERROR(IF(P30-W30=0, "", P30-W30), "") | AA30: =IFERROR(W30+Y30,"") | CF30: 3986 | CG30: 47379 | CH30: 47379 | CI30: 47379 | CJ30: 47379 | CK30: 47379 | CL30: 47379 | CM30: 47379 | CN30: 35068 | CO30: 23914 | CP30: 23914 | CQ30: 23914 | CR30: 23914 | CS30: 23914 | CT30: 23914 | CU30: 23914 | CV30: 23914 | CW30: 1960 | DC30: 14096 | DD30: 21144 | DE30: 21144 | DF30: 21144 | DG30: 21144 | DH30: 68044 | DI30: 68120 | DJ30: 60766 | DK30: 57814 | DL30: 52618 | DM30: 47421 | DN30: 42948 | DO30: 38654 | DP30: 32802 | DQ30: 36200 | DR30: 42369 | DS30: 54028 | DT30: 84605 | DU30: 82760 | DV30: 80173 | DW30: 75219 | DX30: 73327 | DY30: 71387 | DZ30: 68179 | EA30: 64301 | EB30: 51578 | EC30: 42776 | ED30: 40788 | EE30: 37916 | EF30: 33390 | EG30: 26241 | EH30: 2923
A31: 9 | B31: 1CF2010W16A03 | C31: (Main BLDG Complex) FDN Work | D31: 388573 | E31: {=SUMPRODUCT(($AK$2:$GH$2<='S(Week)'!$N$3)*(AK31:GH31)*1)} -> 388570 | F31: =IFERROR(E31*T31,0) -> 388570 | H31: 45444 | I31: 45558 | J31: 97 | T31: =(E32*T32)+(E33*T33)+(E34*T34) -> 1 | V31: =IF(($M31="A")*($O31="A")>0,"Completed",IF($M31="A","In Progress","Not started")) -> Not started | Y31: =IFERROR(IF(P31-W31=0, "", P31-W31), "") | AA31: =IFERROR(W31+Y31,"") | CF31: 3986 | CG31: 23914 | CH31: 23914 | CI31: 23914 | CJ31: 23914 | CK31: 23914 | CL31: 23914 | CM31: 23914 | CN31: 23914 | CO31: 23914 | CP31: 23914 | CQ31: 23914 | CR31: 23914 | CS31: 23914 | CT31: 23914 | CU31: 23914 | CV31: 23914 | CW31: 1960
C32: Excavation | E32: 0.1 | P32: 100 | Q32: % | R32: 100 | S32: % | T32: =IFERROR(P32/R32,0) -> 1 | W32: 100 | X32: % | Y32: =IFERROR(IF(P32-W32=0, "", P32-W32), "") | Z32: % | AA32: =IFERROR(W32+Y32,"") | AB32: % | AC32: Civil | AD32: Zhandos | AE32: Jungmin Kim
C33: Rebar work | E33: 0.4 | P33: 1783568.2 | Q33: Ton | R33: 1783568.2 | S33: Ton | T33: =IFERROR(P33/R33,0) -> 1 | W33: 1783568.2 | X33: Ton | Y33: =IFERROR(IF(P33-W33=0, "", P33-W33), "") | Z33: Ton | AA33: =IFERROR(W33+Y33,"") | AB33: Ton | AC33: Civil | AD33: Zhandos | AE33: Jungmin Kim
C34: Form & Pouring | E34: 0.5 | L34: 16994.8 | M34: M3 | N34: 27903 | O34: M3 | P34: 14834.54 | Q34: M3 | R34: 14834.54 | S34: M3 | T34: =IFERROR(P34/R34,0) -> 1 | W34: 14834.54 | X34: M3 | Y34: =IFERROR(IF(P34-W34=0, "", P34-W34), "") | Z34: M3 | AA34: =IFERROR(W34+Y34,"") | AB34: M3 | AC34: Civil | AD34: Zhandos | AE34: Jungmin Kim
A35: 9 | B35: 1PF2010W20A04P | C35: (Main BLDG Complex) Preparation of Shop Drawing, P.O & Procurement - Structure Work(S/S) | D35: 175406 | E35: {=SUMPRODUCT(($AK$2:$GH$2<='S(Week)'!$N$3)*(AK35:GH35)*1)} -> 175409 | F35: =IFERROR(E35*T35,0) -> 0 | H35: 45446 | I35: 45497 | J35: 45 | Q35: Ton | S35: Ton | T35: =IFERROR($P35/$R35,0) -> 0 | V35: =IF(($M35="A")*($O35="A")>0,"Completed",IF($M35="A","In Progress","Not started")) -> Not started | X35: Ton | Y35: =IFERROR(IF(P35-W35=0, "", P35-W35), "") | Z35: Ton | AA35: =IFERROR(W35+Y35,"") | AB35: Ton | AC35: Arch | AD35: Muratbek | AE35: Dongyob Lee | CG35: 23465 | CH35: 23465 | CI35: 23465 | CJ35: 23465 | CK35: 23465 | CL35: 23465 | CM35: 23465 | CN35: 11154
A36: 9 | B36: 1PF2010W20A05T | C36: (Main BLDG Complex) Transportation - Structure Work(S/S 1st delivery) | D36: 99883 | E36: {=SUMPRODUCT(($AK$2:$GH$2<='S(Week)'!$N$3)*(AK36:GH36)*1)} -> 99883 | F36: =IFERROR(E36*T36,0) -> 0 | H36: 45602 | I36: 45635 | J36: 28 | Q36: Ton | S36: Ton | T36: =IFERROR($P36/$R36,0) -> 0 | V36: =IF(($M36="A")*($O36="A")>0,"Completed",IF($M36="A","In Progress","Not started")) -> Not started | X36: Ton | Y36: =IFERROR(IF(P36-W36=0, "", P36-W36), "") | Z36: Ton | AA36: =IFERROR(W36+Y36,"") | AB36: Ton | AC36: Arch | AD36: Muratbek | AE36: Dongyob Lee | DC36: 14096 | DD36: 21144 | DE36: 21144 | DF36: 21144 | DG36: 21144 | DH36: 1211
A37: 9 | B37: 1CF2010W20A06 | C37: (Main BLDG Complex) Structure Work(S/S) | D37: 678480 | E37: {=SUMPRODUCT(($AK$2:$GH$2<='S(Week)'!$N$3)*(AK37:GH37)*1)} -> 678477 | F37: =IFERROR(E37*T37,0) -> 183234.84 | H37: 45635 | I37: 45814 | J37: 154 | M37: A | P37: =SUM(P38:P45) -> 2813 | Q37: Ton | R37: =SUM(R38:R44) -> 10415.9 | S37: Ton | T37: =IFERROR($P37/$R37,0) -> 0.27006788 | V37: =IF(($M37="A")*($O37="A")>0,"Completed",IF($M37="A","In Progress","Not started")) -> In Progress | W37: 2813 | X37: Ton | Y37: =IFERROR(IF(P37-W37=0, "", P37-W37), "") | Z37: Ton | AA37: =IFERROR(W37+Y37,"") | AB37: Ton | AC37: Arch | AD37: Muratbek | AE37: Dongyob Lee | DH37: 24841 | DI37: 26350 | DJ37: 26350 | DK37: 26350 | DL37: 26350 | DM37: 26350 | DN37: 26350 | DO37: 26350 | DP37: 26350 | DQ37: 26350 | DR37: 26350 | DS37: 26350 | DT37: 26350 | DU37: 26350 | DV37: 26350 | DW37: 26350 | DX37: 26350 | DY37: 26350 | DZ37: 26350 | EA37: 26350 | EB37: 26350 | EC37: 26350 | ED37: 26350 | EE37: 26350 | EF37: 26350 | EG37: 21236
C38: Zone 1 | P38: 1227 | Q38: Ton | R38: 1499.6 | S38: Ton | T38: =IFERROR($P38/$R38,0) -> 0.81821819 | W38: 1227 | X38: Ton | Y38: =IFERROR(IF(P38-W38=0, "", P38-W38), "") | Z38: Ton | AA38: =IFERROR(W38+Y38,"") | AB38: Ton | AC38: Arch | AD38: Muratbek | AE38: Dongyob Lee
C39: Zone 2 | Q39: Ton | R39: 744 | S39: Ton | T39: =IFERROR($P39/$R39,0) -> 0 | X39: Ton | Y39: =IFERROR(IF(P39-W39=0, "", P39-W39), "") | Z39: Ton | AA39: =IFERROR(W39+Y39,"") | AB39: Ton | AC39: Arch | AD39: Muratbek | AE39: Dongyob Lee
C40: Zone 3 | Q40: Ton | R40: 2417.3 | S40: Ton | T40: =IFERROR($P40/$R40,0) -> 0 | X40: Ton | Y40: =IFERROR(IF(P40-W40=0, "", P40-W40), "") | Z40: Ton | AA40: =IFERROR(W40+Y40,"") | AB40: Ton | AC40: Arch | AD40: Muratbek | AE40: Dongyob Lee
...

Sheet Sheet2
A1: Activity ID | B1: Activity Name | C1: Start | D1: Finish | E1: Duration | F1: Budgeted Nonlabor Units | G1: Spreadsheet Field | H1: 45088 | I1: 45095 | J1: 45102 | K1: 45109 | L1: 45116 | M1: 45123 | N1: 45130 | O1: 45137 | P1: 45144 | Q1: 45151 | R1: 45158 | S1: 45165 | T1: 45172 | U1: 45179 | V1: 45186 | W1: 45193 | X1: 45200 | Y1: 45207 | Z1: 45214 | AA1: 45221 | AB1: 45228 | AC1: 45235 | AD1: 45242 | AE1: 45249 | AF1: 45256 | AG1: 45263 | AH1: 45270 | AI1: 45277 | AJ1: 45284 | AK1: 45291 | AL1: 45298 | AM1: 45305 | AN1: 45312 | AO1: 45319 | AP1: 45326 | AQ1: 45333 | AR1: 45340 | AS1: 45347 | AT1: 45354 | AU1: 45361 | AV1: 45368 | AW1: 45375 | AX1: 45382 | AY1: 45389 | AZ1: 45396 | BA1: 45403 | BB1: 45410 | BC1: 45417 | BD1: 45424 | BE1: 45431 | BF1: 45438 | BG1: 45445 | BH1: 45452 | BI1: 45459 | BJ1: 45466 | BK1: 45473 | BL1: 45480 | BM1: 45487 | BN1: 45494 | BO1: 45501 | BP1: 45508 | BQ1: 45515 | BR1: 45522 | BS1: 45529 | BT1: 45536 | BU1: 45543 | BV1: 45550 | BW1: 45557 | BX1: 45564 | BY1: 45571 | BZ1: 45578 | CA1: 45585 | CB1: 45592 | CC1: 45599 | CD1: 45606 | CE1: 45613 | CF1: 45620 | CG1: 45627 | CH1: 45634 | CI1: 45641 | CJ1: 45648 | CK1: 45655 | CL1: 45662 | CM1: 45669 | CN1: 45676 | CO1: 45683 | CP1: 45690 | CQ1: 45697 | CR1: 45704 | CS1: 45711 | CT1: 45718 | CU1: 45725 | CV1: 45732 | CW1: 45739 | CX1: 45746 | CY1: 45753 | CZ1: 45760 | DA1: 45767 | DB1: 45774 | DC1: 45781 | DD1: 45788 | DE1: 45795 | DF1: 45802 | DG1: 45809 | DH1: 45816 | DI1: 45823 | DJ1: 45830 | DK1: 45837 | DL1: 45844 | DM1: 45851 | DN1: 45858 | DO1: 45865 | DP1: 45872 | DQ1: 45879 | DR1: 45886 | DS1: 45893 | DT1: 45900 | DU1: 45907 | DV1: 45914 | DW1: 45921 | DX1: 45928 | DY1: 45935 | DZ1: 45942 | EA1: 45949 | EB1: 45956 | EC1: 45963 | ED1: 45970 | EE1: 45977 | EF1: 45984 | EG1: 45991 | EH1: 45998 | EI1: 46005 | EJ1: 46012 | EK1: 46019 | EL1: 46026 | EM1: 46033 | EN1: 46040 | EO1: 46047 | EP1: 46054 | EQ1: 46061 | ER1: 46068 | ES1: 46075 | ET1: 46082 | EU1: 46089 | EV1: 46096 | EW1: 46103 | EX1: 46110 | EY1: 46117 | EZ1: 46124 | FA1: 46131 | FB1: 46138 | FC1: 46145 | FD1: 46152 | FE1: 46159 | FF1: 46166 | FG1: 46173 | FH1: 46180
A2: Construction of a 1000MW CCGT Power Plant in the Turkistan Region, Main Site_New Site | C2: 45089 | D2: 46181 | E2: 937 | F2: 50102810 | G2: Budgeted Nonlabor Units | P2: 467 | Q2: 467 | R2: 467 | S2: 467 | T2: 467 | U2: 11898 | V2: 34759 | W2: 29273 | X2: 13406 | Y2: 7629 | Z2: 9226 | AA2: 13606 | AB2: 13606 | AC2: 13541 | AD2: 13139 | AE2: 12099 | AF2: 6570 | AG2: 2728 | AM2: 1104 | AN2: 1073 | AO2: 817 | AP2: 543 | AQ2: 266 | AR2: 42 | BC2: 70 | BD2: 551 | BE2: 3058 | BF2: 17583 | BG2: 82476 | BH2: 88153 | BI2: 96368 | BJ2: 153489 | BK2: 235381 | BL2: 294696 | BM2: 434172 | BN2: 472392 | BO2: 378701 | BP2: 286904 | BQ2: 263291 | BR2: 208839 | BS2: 219254 | BT2: 239920 | BU2: 309852 | BV2: 298282 | BW2: 359332 | BX2: 615241 | BY2: 764704 | BZ2: 795831 | CA2: 766045 | CB2: 742097 | CC2: 847236 | CD2: 1030887 | CE2: 875032 | CF2: 743328 | CG2: 780703 | CH2: 790027 | CI2: 544088 | CJ2: 403905 | CK2: 452610 | CL2: 669855 | CM2: 945990 | CN2: 1034870 | CO2: 867829 | CP2: 812973 | CQ2: 861984 | CR2: 804109 | CS2: 547989 | CT2: 609346 | CU2: 505644 | CV2: 454729 | CW2: 565519 | CX2: 426537 | CY2: 332504 | CZ2: 411789 | DA2: 433324 | DB2: 826816 | DC2: 1071411 | DD2: 814336 | DE2: 721060 | DF2: 578530 | DG2: 606317 | DH2: 515061 | DI2: 513031 | DJ2: 608194 | DK2: 981210 | DL2: 1016836 | DM2: 988354 | DN2: 1083102 | DO2: 925063 | DP2: 929038 | DQ2: 1009933 | DR2: 791577 | DS2: 711563 | DT2: 632454 | DU2: 593631 | DV2: 597826 | DW2: 763890 | DX2: 771921 | DY2: 782271 | DZ2: 676671 | EA2: 930283 | EB2: 673632 | EC2: 785599 | ED2: 384719 | EE2: 417420 | EF2: 349677 | EG2: 277631 | EH2: 191653 | EI2: 192659 | EJ2: 163731 | EK2: 187392 | EL2: 177892 | EM2: 86261 | EN2: 72886 | EO2: 62614 | EP2: 52069 | EQ2: 29886 | ER2: 90549 | ES2: 81632 | ET2: 52387 | EU2: 97548 | EV2: 46710 | EW2: 10720 | EX2: 3346 | EY2: 298 | EZ2: 2808 | FA2: 8671 | FB2: 6672 | FC2: 10849 | FD2: 34581 | FE2: 12095 | FF2: 14258 | FG2: 14258 | FH2: 2163
A3: Construction of a 1000MW CCGT Power Plant in the Turkistan Region, Main Site_New Site | C3: 45089 | D3: 46181 | E3: 937 | F3: 50102810 | G3: Cum Budgeted Nonlabor Units | P3: 467 | Q3: 934 | R3: 1401 | S3: 1868 | T3: 2335 | U3: 14232 | V3: 48991 | W3: 78264 | X3: 91670 | Y3: 99300 | Z3: 108526 | AA3: 122132 | AB3: 135739 | AC3: 149280 | AD3: 162419 | AE3: 174518 | AF3: 181088 | AG3: 183816 | AH3: 183816 | AI3: 183816 | AJ3: 183816 | AK3: 183816 | AL3: 183816 | AM3: 184920 | AN3: 185993 | AO3: 186810 | AP3: 187353 | AQ3: 187619 | AR3: 187661 | AS3: 187661 | AT3: 187661 | AU3: 187661 | AV3: 187661 | AW3: 187661 | AX3: 187661 | AY3: 187661 | AZ3: 187661 | BA3: 187661 | BB3: 187661 | BC3: 187731 | BD3: 188283 | BE3: 191341 | BF3: 208923 | BG3: 291400 | BH3: 379553 | BI3: 475920 | BJ3: 629410 | BK3: 864790 | BL3: 1159486 | BM3: 1593658 | BN3: 2066051 | BO3: 2444752 | BP3: 2731656 | BQ3: 2994947 | BR3: 3203786 | BS3: 3423040 | BT3: 3662960 | BU3: 3972812 | BV3: 4271094 | BW3: 4630426 | BX3: 5245667 | BY3: 6010371 | BZ3: 6806202 | CA3: 7572247 | CB3: 8314344 | CC3: 9161580 | CD3: 10192466 | CE3: 11067498 | CF3: 11810826 | CG3: 12591529 | CH3: 13381557 | CI3: 13925644 | CJ3: 14329549 | CK3: 14782158 | CL3: 15452014 | CM3: 16398004 | CN3: 17432874 | CO3: 18300703 | CP3: 19113676 | CQ3: 19975659 | CR3: 20779769 | CS3: 21327758 | CT3: 21937105 | CU3: 22442749 | CV3: 22897478 | CW3: 23462996 | CX3: 23889534 | CY3: 24222037 | CZ3: 24633827 | DA3: 25067151 | DB3: 25893967 | DC3: 26965378 | DD3: 27779714 | DE3: 28500774 | DF3: 29079304 | DG3: 29685621 | DH3: 30200682 | DI3: 30713713 | DJ3: 31321908 | DK3: 32303118 | DL3: 33319955 | DM3: 34308309 | DN3: 35391410 | DO3: 36316473 | DP3: 37245511 | DQ3: 38255444 | DR3: 39047021 | DS3: 39758584 | DT3: 40391038 | DU3: 40984669 | DV3: 41582495 | DW3: 42346384 | DX3: 43118305 | DY3: 43900577 | DZ3: 44577248 | EA3: 45507531 | EB3: 46181163 | EC3: 46966762 | ED3: 47351482 | EE3: 47768902 | EF3: 48118579 | EG3: 48396210 | EH3: 48587863 | EI3: 48780522 | EJ3: 48944252 | EK3: 49131644 | EL3: 49309536 | EM3: 49395797 | EN3: 49468683 | EO3: 49531297 | EP3: 49583366 | EQ3: 49613252 | ER3: 49703801 | ES3: 49785434 | ET3: 49837820 | EU3: 49935368 | EV3: 49982078 | EW3: 49992798 | EX3: 49996143 | EY3: 49996441 | EZ3: 49999249 | FA3: 50007920 | FB3: 50014592 | FC3: 50025441 | FD3: 50060022 | FE3: 50072117 | FF3: 50086375 | FG3: 50100633 | FH3: 50102796
A4: Plant General | C4: 45089 | D4: 45266 | E4: 152 | F4: 177344 | G4: Budgeted Nonlabor Units | U4: 11431 | V4: 34292 | W4: 28806 | X4: 12940 | Y4: 7162 | Z4: 8760 | AA4: 13139 | AB4: 13139 | AC4: 13139 | AD4: 13139 | AE4: 12099 | AF4: 6570 | AG4: 2728
A5: Plant General | C5: 45089 | D5: 45266 | E5: 152 | F5: 177344 | G5: Cum Budgeted Nonlabor Units | U5: 11431 | V5: 45723 | W5: 74528 | X5: 87468 | Y5: 94630 | Z5: 103390 | AA5: 116529 | AB5: 129668 | AC5: 142808 | AD5: 155947 | AE5: 168046 | AF5: 174616 | AG5: 177344 | AH5: 177344 | AI5: 177344 | AJ5: 177344 | AK5: 177344 | AL5: 177344 | AM5: 177344 | AN5: 177344 | AO5: 177344 | AP5: 177344 | AQ5: 177344 | AR5: 177344 | AS5: 177344 | AT5: 177344 | AU5: 177344 | AV5: 177344 | AW5: 177344 | AX5: 177344 | AY5: 177344 | AZ5: 177344 | BA5: 177344 | BB5: 177344 | BC5: 177344 | BD5: 177344 | BE5: 177344 | BF5: 177344 | BG5: 177344 | BH5: 177344 | BI5: 177344 | BJ5: 177344 | BK5: 177344 | BL5: 177344 | BM5: 177344 | BN5: 177344 | BO5: 177344 | BP5: 177344 | BQ5: 177344 | BR5: 177344 | BS5: 177344 | BT5: 177344 | BU5: 177344 | BV5: 177344 | BW5: 177344 | BX5: 177344 | BY5: 177344 | BZ5: 177344 | CA5: 177344 | CB5: 177344 | CC5: 177344 | CD5: 177344 | CE5: 177344 | CF5: 177344 | CG5: 177344 | CH5: 177344 | CI5: 177344 | CJ5: 177344 | CK5: 177344 | CL5: 177344 | CM5: 177344 | CN5: 177344 | CO5: 177344 | CP5: 177344 | CQ5: 177344 | CR5: 177344 | CS5: 177344 | CT5: 177344 | CU5: 177344 | CV5: 177344 | CW5: 177344 | CX5: 177344 | CY5: 177344 | CZ5: 177344 | DA5: 177344 | DB5: 177344 | DC5: 177344 | DD5: 177344 | DE5: 177344 | DF5: 177344 | DG5: 177344 | DH5: 177344 | DI5: 177344 | DJ5: 177344 | DK5: 177344 | DL5: 177344 | DM5: 177344 | DN5: 177344 | DO5: 177344 | DP5: 177344 | DQ5: 177344 | DR5: 177344 | DS5: 177344 | DT5: 177344 | DU5: 177344 | DV5: 177344 | DW5: 177344 | DX5: 177344 | DY5: 177344 | DZ5: 177344 | EA5: 177344 | EB5: 177344 | EC5: 177344 | ED5: 177344 | EE5: 177344 | EF5: 177344 | EG5: 177344 | EH5: 177344 | EI5: 177344 | EJ5: 177344 | EK5: 177344 | EL5: 177344 | EM5: 177344 | EN5: 177344 | EO5: 177344 | EP5: 177344 | EQ5: 177344 | ER5: 177344 | ES5: 177344 | ET5: 177344 | EU5: 177344 | EV5: 177344 | EW5: 177344 | EX5: 177344 | EY5: 177344 | EZ5: 177344 | FA5: 177344 | FB5: 177344 | FC5: 177344 | FD5: 177344 | FE5: 177344 | FF5: 177344 | FG5: 177344 | FH5: 177344
A6: General Civil Works | C6: 45089 | D6: 45266 | E6: 152 | F6: 177344 | G6: Budgeted Nonlabor Units | U6: 11431 | V6: 34292 | W6: 28806 | X6: 12940 | Y6: 7162 | Z6: 8760 | AA6: 13139 | AB6: 13139 | AC6: 13139 | AD6: 13139 | AE6: 12099 | AF6: 6570 | AG6: 2728
A7: General Civil Works | C7: 45089 | D7: 45266 | E7: 152 | F7: 177344 | G7: Cum Budgeted Nonlabor Units | U7: 11431 | V7: 45723 | W7: 74528 | X7: 87468 | Y7: 94630 | Z7: 103390 | AA7: 116529 | AB7: 129668 | AC7: 142808 | AD7: 155947 | AE7: 168046 | AF7: 174616 | AG7: 177344 | AH7: 177344 | AI7: 177344 | AJ7: 177344 | AK7: 177344 | AL7: 177344 | AM7: 177344 | AN7: 177344 | AO7: 177344 | AP7: 177344 | AQ7: 177344 | AR7: 177344 | AS7: 177344 | AT7: 177344 | AU7: 177344 | AV7: 177344 | AW7: 177344 | AX7: 177344 | AY7: 177344 | AZ7: 177344 | BA7: 177344 | BB7: 177344 | BC7: 177344 | BD7: 177344 | BE7: 177344 | BF7: 177344 | BG7: 177344 | BH7: 177344 | BI7: 177344 | BJ7: 177344 | BK7: 177344 | BL7: 177344 | BM7: 177344 | BN7: 177344 | BO7: 177344 | BP7: 177344 | BQ7: 177344 | BR7: 177344 | BS7: 177344 | BT7: 177344 | BU7: 177344 | BV7: 177344 | BW7: 177344 | BX7: 177344 | BY7: 177344 | BZ7: 177344 | CA7: 177344 | CB7: 177344 | CC7: 177344 | CD7: 177344 | CE7: 177344 | CF7: 177344 | CG7: 177344 | CH7: 177344 | CI7: 177344 | CJ7: 177344 | CK7: 177344 | CL7: 177344 | CM7: 177344 | CN7: 177344 | CO7: 177344 | CP7: 177344 | CQ7: 177344 | CR7: 177344 | CS7: 177344 | CT7: 177344 | CU7: 177344 | CV7: 177344 | CW7: 177344 | CX7: 177344 | CY7: 177344 | CZ7: 177344 | DA7: 177344 | DB7: 177344 | DC7: 177344 | DD7: 177344 | DE7: 177344 | DF7: 177344 | DG7: 177344 | DH7: 177344 | DI7: 177344 | DJ7: 177344 | DK7: 177344 | DL7: 177344 | DM7: 177344 | DN7: 177344 | DO7: 177344 | DP7: 177344 | DQ7: 177344 | DR7: 177344 | DS7: 177344 | DT7: 177344 | DU7: 177344 | DV7: 177344 | DW7: 177344 | DX7: 177344 | DY7: 177344 | DZ7: 177344 | EA7: 177344 | EB7: 177344 | EC7: 177344 | ED7: 177344 | EE7: 177344 | EF7: 177344 | EG7: 177344 | EH7: 177344 | EI7: 177344 | EJ7: 177344 | EK7: 177344 | EL7: 177344 | EM7: 177344 | EN7: 177344 | EO7: 177344 | EP7: 177344 | EQ7: 177344 | ER7: 177344 | ES7: 177344 | ET7: 177344 | EU7: 177344 | EV7: 177344 | EW7: 177344 | EX7: 177344 | EY7: 177344 | EZ7: 177344 | FA7: 177344 | FB7: 177344 | FC7: 177344 | FD7: 177344 | FE7: 177344 | FF7: 177344 | FG7: 177344 | FH7: 177344
A8: Site Preparation | C8: 45184 | D8: 45266 | E8: 70 | F8: 177344 | G8: Budgeted Nonlabor Units | U8: 11431 | V8: 34292 | W8: 28806 | X8: 12940 | Y8: 7162 | Z8: 8760 | AA8: 13139 | AB8: 13139 | AC8: 13139 | AD8: 13139 | AE8: 12099 | AF8: 6570 | AG8: 2728
A9: Site Preparation | C9: 45184 | D9: 45266 | E9: 70 | F9: 177344 | G9: Cum Budgeted Nonlabor Units | U9: 11431 | V9: 45723 | W9: 74528 | X9: 87468 | Y9: 94630 | Z9: 103390 | AA9: 116529 | AB9: 129668 | AC9: 142808 | AD9: 155947 | AE9: 168046 | AF9: 174616 | AG9: 177344 | AH9: 177344 | AI9: 177344 | AJ9: 177344 | AK9: 177344 | AL9: 177344 | AM9: 177344 | AN9: 177344 | AO9: 177344 | AP9: 177344 | AQ9: 177344 | AR9: 177344 | AS9: 177344 | AT9: 177344 | AU9: 177344 | AV9: 177344 | AW9: 177344 | AX9: 177344 | AY9: 177344 | AZ9: 177344 | BA9: 177344 | BB9: 177344 | BC9: 177344 | BD9: 177344 | BE9: 177344 | BF9: 177344 | BG9: 177344 | BH9: 177344 | BI9: 177344 | BJ9: 177344 | BK9: 177344 | BL9: 177344 | BM9: 177344 | BN9: 177344 | BO9: 177344 | BP9: 177344 | BQ9: 177344 | BR9: 177344 | BS9: 177344 | BT9: 177344 | BU9: 177344 | BV9: 177344 | BW9: 177344 | BX9: 177344 | BY9: 177344 | BZ9: 177344 | CA9: 177344 | CB9: 177344 | CC9: 177344 | CD9: 177344 | CE9: 177344 | CF9: 177344 | CG9: 177344 | CH9: 177344 | CI9: 177344 | CJ9: 177344 | CK9: 177344 | CL9: 177344 | CM9: 177344 | CN9: 177344 | CO9: 177344 | CP9: 177344 | CQ9: 177344 | CR9: 177344 | CS9: 177344 | CT9: 177344 | CU9: 177344 | CV9: 177344 | CW9: 177344 | CX9: 177344 | CY9: 177344 | CZ9: 177344 | DA9: 177344 | DB9: 177344 | DC9: 177344 | DD9: 177344 | DE9: 177344 | DF9: 177344 | DG9: 177344 | DH9: 177344 | DI9: 177344 | DJ9: 177344 | DK9: 177344 | DL9: 177344 | DM9: 177344 | DN9: 177344 | DO9: 177344 | DP9: 177344 | DQ9: 177344 | DR9: 177344 | DS9: 177344 | DT9: 177344 | DU9: 177344 | DV9: 177344 | DW9: 177344 | DX9: 177344 | DY9: 177344 | DZ9: 177344 | EA9: 177344 | EB9: 177344 | EC9: 177344 | ED9: 177344 | EE9: 177344 | EF9: 177344 | EG9: 177344 | EH9: 177344 | EI9: 177344 | EJ9: 177344 | EK9: 177344 | EL9: 177344 | EM9: 177344 | EN9: 177344 | EO9: 177344 | EP9: 177344 | EQ9: 177344 | ER9: 177344 | ES9: 177344 | ET9: 177344 | EU9: 177344 | EV9: 177344 | EW9: 177344 | EX9: 177344 | EY9: 177344 | EZ9: 177344 | FA9: 177344 | FB9: 177344 | FC9: 177344 | FD9: 177344 | FE9: 177344 | FF9: 177344 | FG9: 177344 | FH9: 177344
A10: Construction Management | C10: 45184 | D10: 45266 | E10: 70 | F10: 88672 | G10: Budgeted Nonlabor Units | U10: 7117 | V10: 21352 | W10: 15866 | Z10: 2190 | AA10: 6570 | AB10: 6570 | AC10: 6570 | AD10: 6570 | AE10: 6570 | AF10: 6570 | AG10: 2728
A11: Construction Management | C11: 45184 | D11: 45266 | E11: 70 | F11: 88672 | G11: Cum Budgeted Nonlabor Units | U11: 7117 | V11: 28470 | W11: 44336 | X11: 44336 | Y11: 44336 | Z11: 46526 | AA11: 53096 | AB11: 59665 | AC11: 66235 | AD11: 72804 | AE11: 79374 | AF11: 85944 | AG11: 88672 | AH11: 88672 | AI11: 88672 | AJ11: 88672 | AK11: 88672 | AL11: 88672 | AM11: 88672 | AN11: 88672 | AO11: 88672 | AP11: 88672 | AQ11: 88672 | AR11: 88672 | AS11: 88672 | AT11: 88672 | AU11: 88672 | AV11: 88672 | AW11: 88672 | AX11: 88672 | AY11: 88672 | AZ11: 88672 | BA11: 88672 | BB11: 88672 | BC11: 88672 | BD11: 88672 | BE11: 88672 | BF11: 88672 | BG11: 88672 | BH11: 88672 | BI11: 88672 | BJ11: 88672 | BK11: 88672 | BL11: 88672 | BM11: 88672 | BN11: 88672 | BO11: 88672 | BP11: 88672 | BQ11: 88672 | BR11: 88672 | BS11: 88672 | BT11: 88672 | BU11: 88672 | BV11: 88672 | BW11: 88672 | BX11: 88672 | BY11: 88672 | BZ11: 88672 | CA11: 88672 | CB11: 88672 | CC11: 88672 | CD11: 88672 | CE11: 88672 | CF11: 88672 | CG11: 88672 | CH11: 88672 | CI11: 88672 | CJ11: 88672 | CK11: 88672 | CL11: 88672 | CM11: 88672 | CN11: 88672 | CO11: 88672 | CP11: 88672 | CQ11: 88672 | CR11: 88672 | CS11: 88672 | CT11: 88672 | CU11: 88672 | CV11: 88672 | CW11: 88672 | CX11: 88672 | CY11: 88672 | CZ11: 88672 | DA11: 88672 | DB11: 88672 | DC11: 88672 | DD11: 88672 | DE11: 88672 | DF11: 88672 | DG11: 88672 | DH11: 88672 | DI11: 88672 | DJ11: 88672 | DK11: 88672 | DL11: 88672 | DM11: 88672 | DN11: 88672 | DO11: 88672 | DP11: 88672 | DQ11: 88672 | DR11: 88672 | DS11: 88672 | DT11: 88672 | DU11: 88672 | DV11: 88672 | DW11: 88672 | DX11: 88672 | DY11: 88672 | DZ11: 88672 | EA11: 88672 | EB11: 88672 | EC11: 88672 | ED11: 88672 | EE11: 88672 | EF11: 88672 | EG11: 88672 | EH11: 88672 | EI11: 88672 | EJ11: 88672 | EK11: 88672 | EL11: 88672 | EM11: 88672 | EN11: 88672 | EO11: 88672 | EP11: 88672 | EQ11: 88672 | ER11: 88672 | ES11: 88672 | ET11: 88672 | EU11: 88672 | EV11: 88672 | EW11: 88672 | EX11: 88672 | EY11: 88672 | EZ11: 88672 | FA11: 88672 | FB11: 88672 | FC11: 88672 | FD11: 88672 | FE11: 88672 | FF11: 88672 | FG11: 88672 | FH11: 88672
A12: Civil & Architecture Team | C12: 45184 | D12: 45266 | E12: 70 | F12: 88672 | G12: Budgeted Nonlabor Units | U12: 7117 | V12: 21352 | W12: 15866 | Z12: 2190 | AA12: 6570 | AB12: 6570 | AC12: 6570 | AD12: 6570 | AE12: 6570 | AF12: 6570 | AG12: 2728
A13: Civil & Architecture Team | C13: 45184 | D13: 45266 | E13: 70 | F13: 88672 | G13: Cum Budgeted Nonlabor Units | U13: 7117 | V13: 28470 | W13: 44336 | X13: 44336 | Y13: 44336 | Z13: 46526 | AA13: 53096 | AB13: 59665 | AC13: 66235 | AD13: 72804 | AE13: 79374 | AF13: 85944 | AG13: 88672 | AH13: 88672 | AI13: 88672 | AJ13: 88672 | AK13: 88672 | AL13: 88672 | AM13: 88672 | AN13: 88672 | AO13: 88672 | AP13: 88672 | AQ13: 88672 | AR13: 88672 | AS13: 88672 | AT13: 88672 | AU13: 88672 | AV13: 88672 | AW13: 88672 | AX13: 88672 | AY13: 88672 | AZ13: 88672 | BA13: 88672 | BB13: 88672 | BC13: 88672 | BD13: 88672 | BE13: 88672 | BF13: 88672 | BG13: 88672 | BH13: 88672 | BI13: 88672 | BJ13: 88672 | BK13: 88672 | BL13: 88672 | BM13: 88672 | BN13: 88672 | BO13: 88672 | BP13: 88672 | BQ13: 88672 | BR13: 88672 | BS13: 88672 | BT13: 88672 | BU13: 88672 | BV13: 88672 | BW13: 88672 | BX13: 88672 | BY13: 88672 | BZ13: 88672 | CA13: 88672 | CB13: 88672 | CC13: 88672 | CD13: 88672 | CE13: 88672 | CF13: 88672 | CG13: 88672 | CH13: 88672 | CI13: 88672 | CJ13: 88672 | CK13: 88672 | CL13: 88672 | CM13: 88672 | CN13: 88672 | CO13: 88672 | CP13: 88672 | CQ13: 88672 | CR13: 88672 | CS13: 88672 | CT13: 88672 | CU13: 88672 | CV13: 88672 | CW13: 88672 | CX13: 88672 | CY13: 88672 | CZ13: 88672 | DA13: 88672 | DB13: 88672 | DC13: 88672 | DD13: 88672 | DE13: 88672 | DF13: 88672 | DG13: 88672 | DH13: 88672 | DI13: 88672 | DJ13: 88672 | DK13: 88672 | DL13: 88672 | DM13: 88672 | DN13: 88672 | DO13: 88672 | DP13: 88672 | DQ13: 88672 | DR13: 88672 | DS13: 88672 | DT13: 88672 | DU13: 88672 | DV13: 88672 | DW13: 88672 | DX13: 88672 | DY13: 88672 | DZ13: 88672 | EA13: 88672 | EB13: 88672 | EC13: 88672 | ED13: 88672 | EE13: 88672 | EF13: 88672 | EG13: 88672 | EH13: 88672 | EI13: 88672 | EJ13: 88672 | EK13: 88672 | EL13: 88672 | EM13: 88672 | EN13: 88672 | EO13: 88672 | EP13: 88672 | EQ13: 88672 | ER13: 88672 | ES13: 88672 | ET13: 88672 | EU13: 88672 | EV13: 88672 | EW13: 88672 | EX13: 88672 | EY13: 88672 | EZ13: 88672 | FA13: 88672 | FB13: 88672 | FC13: 88672 | FD13: 88672 | FE13: 88672 | FF13: 88672 | FG13: 88672 | FH13: 88672
A14: 0CF6010W10A7 | B14: Construction Permit & Mobilization | C14: 45184 | D14: 45198 | E14: 12 | F14: 44336 | G14: Budgeted Nonlabor Units | U14: 7117 | V14: 21352 | W14: 15866
A15: 0CF6010W10A7 | B15: Construction Permit & Mobilization | C15: 45184 | D15: 45198 | E15: 12 | F15: 44336 | G15: Cum Budgeted Nonlabor Units | U15: 7117 | V15: 28470 | W15: 44336 | X15: 44336 | Y15: 44336 | Z15: 44336 | AA15: 44336 | AB15: 44336 | AC15: 44336 | AD15: 44336 | AE15: 44336 | AF15: 44336 | AG15: 44336 | AH15: 44336 | AI15: 44336 | AJ15: 44336 | AK15: 44336 | AL15: 44336 | AM15: 44336 | AN15: 44336 | AO15: 44336 | AP15: 44336 | AQ15: 44336 | AR15: 44336 | AS15: 44336 | AT15: 44336 | AU15: 44336 | AV15: 44336 | AW15: 44336 | AX15: 44336 | AY15: 44336 | AZ15: 44336 | BA15: 44336 | BB15: 44336 | BC15: 44336 | BD15: 44336 | BE15: 44336 | BF15: 44336 | BG15: 44336 | BH15: 44336 | BI15: 44336 | BJ15: 44336 | BK15: 44336 | BL15: 44336 | BM15: 44336 | BN15: 44336 | BO15: 44336 | BP15: 44336 | BQ15: 44336 | BR15: 44336 | BS15: 44336 | BT15: 44336 | BU15: 44336 | BV15: 44336 | BW15: 44336 | BX15: 44336 | BY15: 44336 | BZ15: 44336 | CA15: 44336 | CB15: 44336 | CC15: 44336 | CD15: 44336 | CE15: 44336 | CF15: 44336 | CG15: 44336 | CH15: 44336 | CI15: 44336 | CJ15: 44336 | CK15: 44336 | CL15: 44336 | CM15: 44336 | CN15: 44336 | CO15: 44336 | CP15: 44336 | CQ15: 44336 | CR15: 44336 | CS15: 44336 | CT15: 44336 | CU15: 44336 | CV15: 44336 | CW15: 44336 | CX15: 44336 | CY15: 44336 | CZ15: 44336 | DA15: 44336 | DB15: 44336 | DC15: 44336 | DD15: 44336 | DE15: 44336 | DF15: 44336 | DG15: 44336 | DH15: 44336 | DI15: 44336 | DJ15: 44336 | DK15: 44336 | DL15: 44336 | DM15: 44336 | DN15: 44336 | DO15: 44336 | DP15: 44336 | DQ15: 44336 | DR15: 44336 | DS15: 44336 | DT15: 44336 | DU15: 44336 | DV15: 44336 | DW15: 44336 | DX15: 44336 | DY15: 44336 | DZ15: 44336 | EA15: 44336 | EB15: 44336 | EC15: 44336 | ED15: 44336 | EE15: 44336 | EF15: 44336 | EG15: 44336 | EH15: 44336 | EI15: 44336 | EJ15: 44336 | EK15: 44336 | EL15: 44336 | EM15: 44336 | EN15: 44336 | EO15: 44336 | EP15: 44336 | EQ15: 44336 | ER15: 44336 | ES15: 44336 | ET15: 44336 | EU15: 44336 | EV15: 44336 | EW15: 44336 | EX15: 44336 | EY15: 44336 | EZ15: 44336 | FA15: 44336 | FB15: 44336 | FC15: 44336 | FD15: 44336 | FE15: 44336 | FF15: 44336 | FG15: 44336 | FH15: 44336
A16: 0CF6010W10A13 | B16: Temp. Facilities(Office & Camp, Fence Concrete Batch Plant & Others) | C16: 45219 | D16: 45266 | E16: 40 | F16: 44336 | G16: Budgeted Nonlabor Units | Z16: 2190 | AA16: 6570 | AB16: 6570 | AC16: 6570 | AD16: 6570 | AE16: 6570 | AF16: 6570 | AG16: 2728
A17: 0CF6010W10A13 | B17: Temp. Facilities(Office & Camp, Fence Concrete Batch Plant & Others) | C17: 45219 | D17: 45266 | E17: 40 | F17: 44336 | G17: Cum Budgeted Nonlabor Units | Z17: 2190 | AA17: 8760 | AB17: 15329 | AC17: 21899 | AD17: 28468 | AE17: 35038 | AF17: 41608 | AG17: 44336 | AH17: 44336 | AI17: 44336 | AJ17: 44336 | AK17: 44336 | AL17: 44336 | AM17: 44336 | AN17: 44336 | AO17: 44336 | AP17: 44336 | AQ17: 44336 | AR17: 44336 | AS17: 44336 | AT17: 44336 | AU17: 44336 | AV17: 44336 | AW17: 44336 | AX17: 44336 | AY17: 44336 | AZ17: 44336 | BA17: 44336 | BB17: 44336 | BC17: 44336 | BD17: 44336 | BE17: 44336 | BF17: 44336 | BG17: 44336 | BH17: 44336 | BI17: 44336 | BJ17: 44336 | BK17: 44336 | BL17: 44336 | BM17: 44336 | BN17: 44336 | BO17: 44336 | BP17: 44336 | BQ17: 44336 | BR17: 44336 | BS17: 44336 | BT17: 44336 | BU17: 44336 | BV17: 44336 | BW17: 44336 | BX17: 44336 | BY17: 44336 | BZ17: 44336 | CA17: 44336 | CB17: 44336 | CC17: 44336 | CD17: 44336 | CE17: 44336 | CF17: 44336 | CG17: 44336 | CH17: 44336 | CI17: 44336 | CJ17: 44336 | CK17: 44336 | CL17: 44336 | CM17: 44336 | CN17: 44336 | CO17: 44336 | CP17: 44336 | CQ17: 44336 | CR17: 44336 | CS17: 44336 | CT17: 44336 | CU17: 44336 | CV17: 44336 | CW17: 44336 | CX17: 44336 | CY17: 44336 | CZ17: 44336 | DA17: 44336 | DB17: 44336 | DC17: 44336 | DD17: 44336 | DE17: 44336 | DF17: 44336 | DG17: 44336 | DH17: 44336 | DI17: 44336 | DJ17: 44336 | DK17: 44336 | DL17: 44336 | DM17: 44336 | DN17: 44336 | DO17: 44336 | DP17: 44336 | DQ17: 44336 | DR17: 44336 | DS17: 44336 | DT17: 44336 | DU17: 44336 | DV17: 44336 | DW17: 44336 | DX17: 44336 | DY17: 44336 | DZ17: 44336 | EA17: 44336 | EB17: 44336 | EC17: 44336 | ED17: 44336 | EE17: 44336 | EF17: 44336 | EG17: 44336 | EH17: 44336 | EI17: 44336 | EJ17: 44336 | EK17: 44336 | EL17: 44336 | EM17: 44336 | EN17: 44336 | EO17: 44336 | EP17: 44336 | EQ17: 44336 | ER17: 44336 | ES17: 44336 | ET17: 44336 | EU17: 44336 | EV17: 44336 | EW17: 44336 | EX17: 44336 | EY17: 44336 | EZ17: 44336 | FA17: 44336 | FB17: 44336 | FC17: 44336 | FD17: 44336 | FE17: 44336 | FF17: 44336 | FG17: 44336 | FH17: 44336
A18: Survey & Soil Investigation | C18: 45184 | D18: 45208 | E18: 21 | F18: 44336 | G18: Budgeted Nonlabor Units | U18: 4313 | V18: 12940 | W18: 12940 | X18: 12940 | Y18: 1204
A19: Survey & Soil Investigation | C19: 45184 | D19: 45208 | E19: 21 | F19: 44336 | G19: Cum Budgeted Nonlabor Units | U19: 4313 | V19: 17253 | W19: 30192 | X19: 43132 | Y19: 44336 | Z19: 44336 | AA19: 44336 | AB19: 44336 | AC19: 44336 | AD19: 44336 | AE19: 44336 | AF19: 44336 | AG19: 44336 | AH19: 44336 | AI19: 44336 | AJ19: 44336 | AK19: 44336 | AL19: 44336 | AM19: 44336 | AN19: 44336 | AO19: 44336 | AP19: 44336 | AQ19: 44336 | AR19: 44336 | AS19: 44336 | AT19: 44336 | AU19: 44336 | AV19: 44336 | AW19: 44336 | AX19: 44336 | AY19: 44336 | AZ19: 44336 | BA19: 44336 | BB19: 44336 | BC19: 44336 | BD19: 44336 | BE19: 44336 | BF19: 44336 | BG19: 44336 | BH19: 44336 | BI19: 44336 | BJ19: 44336 | BK19: 44336 | BL19: 44336 | BM19: 44336 | BN19: 44336 | BO19: 44336 | BP19: 44336 | BQ19: 44336 | BR19: 44336 | BS19: 44336 | BT19: 44336 | BU19: 44336 | BV19: 44336 | BW19: 44336 | BX19: 44336 | BY19: 44336 | BZ19: 44336 | CA19: 44336 | CB19: 44336 | CC19: 44336 | CD19: 44336 | CE19: 44336 | CF19: 44336 | CG19: 44336 | CH19: 44336 | CI19: 44336 | CJ19: 44336 | CK19: 44336 | CL19: 44336 | CM19: 44336 | CN19: 44336 | CO19: 44336 | CP19: 44336 | CQ19: 44336 | CR19: 44336 | CS19: 44336 | CT19: 44336 | CU19: 44336 | CV19: 44336 | CW19: 44336 | CX19: 44336 | CY19: 44336 | CZ19: 44336 | DA19: 44336 | DB19: 44336 | DC19: 44336 | DD19: 44336 | DE19: 44336 | DF19: 44336 | DG19: 44336 | DH19: 44336 | DI19: 44336 | DJ19: 44336 | DK19: 44336 | DL19: 44336 | DM19: 44336 | DN19: 44336 | DO19: 44336 | DP19: 44336 | DQ19: 44336 | DR19: 44336 | DS19: 44336 | DT19: 44336 | DU19: 44336 | DV19: 44336 | DW19: 44336 | DX19: 44336 | DY19: 44336 | DZ19: 44336 | EA19: 44336 | EB19: 44336 | EC19: 44336 | ED19: 44336 | EE19: 44336 | EF19: 44336 | EG19: 44336 | EH19: 44336 | EI19: 44336 | EJ19: 44336 | EK19: 44336 | EL19: 44336 | EM19: 44336 | EN19: 44336 | EO19: 44336 | EP19: 44336 | EQ19: 44336 | ER19: 44336 | ES19: 44336 | ET19: 44336 | EU19: 44336 | EV19: 44336 | EW19: 44336 | EX19: 44336 | EY19: 44336 | EZ19: 44336 | FA19: 44336 | FB19: 44336 | FC19: 44336 | FD19: 44336 | FE19: 44336 | FF19: 44336 | FG19: 44336 | FH19: 44336
A20: Construction Management | C20: 45184 | D20: 45208 | E20: 21 | F20: 44336 | G20: Budgeted Nonlabor Units | U20: 4313 | V20: 12940 | W20: 12940 | X20: 12940 | Y20: 1204
A21: Construction Management | C21: 45184 | D21: 45208 | E21: 21 | F21: 44336 | G21: Cum Budgeted Nonlabor Units | U21: 4313 | V21: 17253 | W21: 30192 | X21: 43132 | Y21: 44336 | Z21: 44336 | AA21: 44336 | AB21: 44336 | AC21: 44336 | AD21: 44336 | AE21: 44336 | AF21: 44336 | AG21: 44336 | AH21: 44336 | AI21: 44336 | AJ21: 44336 | AK21: 44336 | AL21: 44336 | AM21: 44336 | AN21: 44336 | AO21: 44336 | AP21: 44336 | AQ21: 44336 | AR21: 44336 | AS21: 44336 | AT21: 44336 | AU21: 44336 | AV21: 44336 | AW21: 44336 | AX21: 44336 | AY21: 44336 | AZ21: 44336 | BA21: 44336 | BB21: 44336 | BC21: 44336 | BD21: 44336 | BE21: 44336 | BF21: 44336 | BG21: 44336 | BH21: 44336 | BI21: 44336 | BJ21: 44336 | BK21: 44336 | BL21: 44336 | BM21: 44336 | BN21: 44336 | BO21: 44336 | BP21: 44336 | BQ21: 44336 | BR21: 44336 | BS21: 44336 | BT21: 44336 | BU21: 44336 | BV21: 44336 | BW21: 44336 | BX21: 44336 | BY21: 44336 | BZ21: 44336 | CA21: 44336 | CB21: 44336 | CC21: 44336 | CD21: 44336 | CE21: 44336 | CF21: 44336 | CG21: 44336 | CH21: 44336 | CI21: 44336 | CJ21: 44336 | CK21: 44336 | CL21: 44336 | CM21: 44336 | CN21: 44336 | CO21: 44336 | CP21: 44336 | CQ21: 44336 | CR21: 44336 | CS21: 44336 | CT21: 44336 | CU21: 44336 | CV21: 44336 | CW21: 44336 | CX21: 44336 | CY21: 44336 | CZ21: 44336 | DA21: 44336 | DB21: 44336 | DC21: 44336 | DD21: 44336 | DE21: 44336 | DF21: 44336 | DG21: 44336 | DH21: 44336 | DI21: 44336 | DJ21: 44336 | DK21: 44336 | DL21: 44336 | DM21: 44336 | DN21: 44336 | DO21: 44336 | DP21: 44336 | DQ21: 44336 | DR21: 44336 | DS21: 44336 | DT21: 44336 | DU21: 44336 | DV21: 44336 | DW21: 44336 | DX21: 44336 | DY21: 44336 | DZ21: 44336 | EA21: 44336 | EB21: 44336 | EC21: 44336 | ED21: 44336 | EE21: 44336 | EF21: 44336 | EG21: 44336 | EH21: 44336 | EI21: 44336 | EJ21: 44336 | EK21: 44336 | EL21: 44336 | EM21: 44336 | EN21: 44336 | EO21: 44336 | EP21: 44336 | EQ21: 44336 | ER21: 44336 | ES21: 44336 | ET21: 44336 | EU21: 44336 | EV21: 44336 | EW21: 44336 | EX21: 44336 | EY21: 44336 | EZ21: 44336 | FA21: 44336 | FB21: 44336 | FC21: 44336 | FD21: 44336 | FE21: 44336 | FF21: 44336 | FG21: 44336 | FH21: 44336
A22: Civil & Architecture Team | C22: 45184 | D22: 45208 | E22: 21 | F22: 44336 | G22: Budgeted Nonlabor Units | U22: 4313 | V22: 12940 | W22: 12940 | X22: 12940 | Y22: 1204
A23: Civil & Architecture Team | C23: 45184 | D23: 45208 | E23: 21 | F23: 44336 | G23: Cum Budgeted Nonlabor Units | U23: 4313 | V23: 17253 | W23: 30192 | X23: 43132 | Y23: 44336 | Z23: 44336 | AA23: 44336 | AB23: 44336 | AC23: 44336 | AD23: 44336 | AE23: 44336 | AF23: 44336 | AG23: 44336 | AH23: 44336 | AI23: 44336 | AJ23: 44336 | AK23: 44336 | AL23: 44336 | AM23: 44336 | AN23: 44336 | AO23: 44336 | AP23: 44336 | AQ23: 44336 | AR23: 44336 | AS23: 44336 | AT23: 44336 | AU23: 44336 | AV23: 44336 | AW23: 44336 | AX23: 44336 | AY23: 44336 | AZ23: 44336 | BA23: 44336 | BB23: 44336 | BC23: 44336 | BD23: 44336 | BE23: 44336 | BF23: 44336 | BG23: 44336 | BH23: 44336 | BI23: 44336 | BJ23: 44336 | BK23: 44336 | BL23: 44336 | BM23: 44336 | BN23: 44336 | BO23: 44336 | BP23: 44336 | BQ23: 44336 | BR23: 44336 | BS23: 44336 | BT23: 44336 | BU23: 44336 | BV23: 44336 | BW23: 44336 | BX23: 44336 | BY23: 44336 | BZ23: 44336 | CA23: 44336 | CB23: 44336 | CC23: 44336 | CD23: 44336 | CE23: 44336 | CF23: 44336 | CG23: 44336 | CH23: 44336 | CI23: 44336 | CJ23: 44336 | CK23: 44336 | CL23: 44336 | CM23: 44336 | CN23: 44336 | CO23: 44336 | CP23: 44336 | CQ23: 44336 | CR23: 44336 | CS23: 44336 | CT23: 44336 | CU23: 44336 | CV23: 44336 | CW23: 44336 | CX23: 44336 | CY23: 44336 | CZ23: 44336 | DA23: 44336 | DB23: 44336 | DC23: 44336 | DD23: 44336 | DE23: 44336 | DF23: 44336 | DG23: 44336 | DH23: 44336 | DI23: 44336 | DJ23: 44336 | DK23: 44336 | DL23: 44336 | DM23: 44336 | DN23: 44336 | DO23: 44336 | DP23: 44336 | DQ23: 44336 | DR23: 44336 | DS23: 44336 | DT23: 44336 | DU23: 44336 | DV23: 44336 | DW23: 44336 | DX23: 44336 | DY23: 44336 | DZ23: 44336 | EA23: 44336 | EB23: 44336 | EC23: 44336 | ED23: 44336 | EE23: 44336 | EF23: 44336 | EG23: 44336 | EH23: 44336 | EI23: 44336 | EJ23: 44336 | EK23: 44336 | EL23: 44336 | EM23: 44336 | EN23: 44336 | EO23: 44336 | EP23: 44336 | EQ23: 44336 | ER23: 44336 | ES23: 44336 | ET23: 44336 | EU23: 44336 | EV23: 44336 | EW23: 44336 | EX23: 44336 | EY23: 44336 | EZ23: 44336 | FA23: 44336 | FB23: 44336 | FC23: 44336 | FD23: 44336 | FE23: 44336 | FF23: 44336 | FG23: 44336 | FH23: 44336
A24: 0CF6010W10A8 | B24: Soil investigation | C24: 45184 | D24: 45208 | E24: 21 | F24: 44336 | G24: Budgeted Nonlabor Units | U24: 4313 | V24: 12940 | W24: 12940 | X24: 12940 | Y24: 1204
A25: 0CF6010W10A8 | B25: Soil investigation | C25: 45184 | D25: 45208 | E25: 21 | F25: 44336 | G25: Cum Budgeted Nonlabor Units | U25: 4313 | V25: 17253 | W25: 30192 | X25: 43132 | Y25: 44336 | Z25: 44336 | AA25: 44336 | AB25: 44336 | AC25: 44336 | AD25: 44336 | AE25: 44336 | AF25: 44336 | AG25: 44336 | AH25: 44336 | AI25: 44336 | AJ25: 44336 | AK25: 44336 | AL25: 44336 | AM25: 44336 | AN25: 44336 | AO25: 44336 | AP25: 44336 | AQ25: 44336 | AR25: 44336 | AS25: 44336 | AT25: 44336 | AU25: 44336 | AV25: 44336 | AW25: 44336 | AX25: 44336 | AY25: 44336 | AZ25: 44336 | BA25: 44336 | BB25: 44336 | BC25: 44336 | BD25: 44336 | BE25: 44336 | BF25: 44336 | BG25: 44336 | BH25: 44336 | BI25: 44336 | BJ25: 44336 | BK25: 44336 | BL25: 44336 | BM25: 44336 | BN25: 44336 | BO25: 44336 | BP25: 44336 | BQ25: 44336 | BR25: 44336 | BS25: 44336 | BT25: 44336 | BU25: 44336 | BV25: 44336 | BW25: 44336 | BX25: 44336 | BY25: 44336 | BZ25: 44336 | CA25: 44336 | CB25: 44336 | CC25: 44336 | CD25: 44336 | CE25: 44336 | CF25: 44336 | CG25: 44336 | CH25: 44336 | CI25: 44336 | CJ25: 44336 | CK25: 44336 | CL25: 44336 | CM25: 44336 | CN25: 44336 | CO25: 44336 | CP25: 44336 | CQ25: 44336 | CR25: 44336 | CS25: 44336 | CT25: 44336 | CU25: 44336 | CV25: 44336 | CW25: 44336 | CX25: 44336 | CY25: 44336 | CZ25: 44336 | DA25: 44336 | DB25: 44336 | DC25: 44336 | DD25: 44336 | DE25: 44336 | DF25: 44336 | DG25: 44336 | DH25: 44336 | DI25: 44336 | DJ25: 44336 | DK25: 44336 | DL25: 44336 | DM25: 44336 | DN25: 44336 | DO25: 44336 | DP25: 44336 | DQ25: 44336 | DR25: 44336 | DS25: 44336 | DT25: 44336 | DU25: 44336 | DV25: 44336 | DW25: 44336 | DX25: 44336 | DY25: 44336 | DZ25: 44336 | EA25: 44336 | EB25: 44336 | EC25: 44336 | ED25: 44336 | EE25: 44336 | EF25: 44336 | EG25: 44336 | EH25: 44336 | EI25: 44336 | EJ25: 44336 | EK25: 44336 | EL25: 44336 | EM25: 44336 | EN25: 44336 | EO25: 44336 | EP25: 44336 | EQ25: 44336 | ER25: 44336 | ES25: 44336 | ET25: 44336 | EU25: 44336 | EV25: 44336 | EW25: 44336 | EX25: 44336 | EY25: 44336 | EZ25: 44336 | FA25: 44336 | FB25: 44336 | FC25: 44336 | FD25: 44336 | FE25: 44336 | FF25: 44336 | FG25: 44336 | FH25: 44336
A26: Soil Improvement | C26: 45208 | D26: 45255 | E26: 40 | F26: 44336 | G26: Budgeted Nonlabor Units | Y26: 5958 | Z26: 6570 | AA26: 6570 | AB26: 6570 | AC26: 6570 | AD26: 6570 | AE26: 5529
A27: Soil Improvement | C27: 45208 | D27: 45255 | E27: 40 | F27: 44336 | G27: Cum Budgeted Nonlabor Units | Y27: 5958 | Z27: 12528 | AA27: 19098 | AB27: 25667 | AC27: 32237 | AD27: 38807 | AE27: 44336 | AF27: 44336 | AG27: 44336 | AH27: 44336 | AI27: 44336 | AJ27: 44336 | AK27: 44336 | AL27: 44336 | AM27: 44336 | AN27: 44336 | AO27: 44336 | AP27: 44336 | AQ27: 44336 | AR27: 44336 | AS27: 44336 | AT27: 44336 | AU27: 44336 | AV27: 44336 | AW27: 44336 | AX27: 44336 | AY27: 44336 | AZ27: 44336 | BA27: 44336 | BB27: 44336 | BC27: 44336 | BD27: 44336 | BE27: 44336 | BF27: 44336 | BG27: 44336 | BH27: 44336 | BI27: 44336 | BJ27: 44336 | BK27: 44336 | BL27: 44336 | BM27: 44336 | BN27: 44336 | BO27: 44336 | BP27: 44336 | BQ27: 44336 | BR27: 44336 | BS27: 44336 | BT27: 44336 | BU27: 44336 | BV27: 44336 | BW27: 44336 | BX27: 44336 | BY27: 44336 | BZ27: 44336 | CA27: 44336 | CB27: 44336 | CC27: 44336 | CD27: 44336 | CE27: 44336 | CF27: 44336 | CG27: 44336 | CH27: 44336 | CI27: 44336 | CJ27: 44336 | CK27: 44336 | CL27: 44336 | CM27: 44336 | CN27: 44336 | CO27: 44336 | CP27: 44336 | CQ27: 44336 | CR27: 44336 | CS27: 44336 | CT27: 44336 | CU27: 44336 | CV27: 44336 | CW27: 44336 | CX27: 44336 | CY27: 44336 | CZ27: 44336 | DA27: 44336 | DB27: 44336 | DC27: 44336 | DD27: 44336 | DE27: 44336 | DF27: 44336 | DG27: 44336 | DH27: 44336 | DI27: 44336 | DJ27: 44336 | DK27: 44336 | DL27: 44336 | DM27: 44336 | DN27: 44336 | DO27: 44336 | DP27: 44336 | DQ27: 44336 | DR27: 44336 | DS27: 44336 | DT27: 44336 | DU27: 44336 | DV27: 44336 | DW27: 44336 | DX27: 44336 | DY27: 44336 | DZ27: 44336 | EA27: 44336 | EB27: 44336 | EC27: 44336 | ED27: 44336 | EE27: 44336 | EF27: 44336 | EG27: 44336 | EH27: 44336 | EI27: 44336 | EJ27: 44336 | EK27: 44336 | EL27: 44336 | EM27: 44336 | EN27: 44336 | EO27: 44336 | EP27: 44336 | EQ27: 44336 | ER27: 44336 | ES27: 44336 | ET27: 44336 | EU27: 44336 | EV27: 44336 | EW27: 44336 | EX27: 44336 | EY27: 44336 | EZ27: 44336 | FA27: 44336 | FB27: 44336 | FC27: 44336 | FD27: 44336 | FE27: 44336 | FF27: 44336 | FG27: 44336 | FH27: 44336
A28: Construction Management | C28: 45208 | D28: 45255 | E28: 40 | F28: 44336 | G28: Budgeted Nonlabor Units | Y28: 5958 | Z28: 6570 | AA28: 6570 | AB28: 6570 | AC28: 6570 | AD28: 6570 | AE28: 5529
